Workbook

Sheet List
B2: 구분 | C2: 프로그램 ID | D2: 프로그램 명 | E2: 담당자 | F2: 진행상태 | H2: 진행상태 | I2: 피재석 | J2: 정일환 | K2: 정유림 | L2: 김다은 | M2: 정혜란
B3: Activity Master | C3: ZLPAC0016 | D3: Log Collect Exception message ID | E3: =VLOOKUP($B3,담당자!$C:$D,2,FALSE) -> 피재석 | F3: 검토중 | H3: 완료 | I3: =COUNTIFS($E:$E,"피재석",$F:$F,"완료") -> 0 | J3: =COUNTIFS($E:$E,"정일환",$F:$F,"완료") -> 0 | K3: =COUNTIFS($E:$E,"정유림",$F:$F,"완료") -> 0 | L3: =COUNTIFS($E:$E,"김다은",$F:$F,"완료") -> 0 | M3: =COUNTIFS($E:$E,"정혜란",$F:$F,"완료") -> 0
B4: Activity Master | C4: ZLPAC0020 | D4: Define Activity Master | E4: =VLOOKUP($B4,담당자!$C:$D,2,FALSE) -> 피재석 | F4: 진행중 | H4: 진행중 | I4: =COUNTIFS($E:$E,"피재석",$F:$F,"진행중") -> 1 | J4: =COUNTIFS($E:$E,"정일환",$F:$F,"진행중") -> 0 | K4: =COUNTIFS($E:$E,"정유림",$F:$F,"진행중") -> 0 | L4: =COUNTIFS($E:$E,"김다은",$F:$F,"진행중") -> 0 | M4: =COUNTIFS($E:$E,"정혜란",$F:$F,"진행중") -> 0
B5: Activity Master | C5: ZLPAC0070 | D5: Define Trigger Code | E5: =VLOOKUP($B5,담당자!$C:$D,2,FALSE) -> 피재석 | F5: 검토중 | H5: 미시작 | I5: =COUNTIFS($E:$E,"피재석",$F:$F,"미시작") -> 0 | J5: =COUNTIFS($E:$E,"정일환",$F:$F,"미시작") -> 0 | K5: =COUNTIFS($E:$E,"정유림",$F:$F,"미시작") -> 0 | L5: =COUNTIFS($E:$E,"김다은",$F:$F,"미시작") -> 0 | M5: =COUNTIFS($E:$E,"정혜란",$F:$F,"미시작") -> 0
B6: Activity Master | C6: ZLPAC0072 | D6: Define Common Log Parameter | E6: =VLOOKUP($B6,담당자!$C:$D,2,FALSE) -> 피재석 | F6: 검토중 | H6: 검토중 | I6: =COUNTIFS($E:$E,"피재석",$F:$F,"검토중") -> 20 | J6: =COUNTIFS($E:$E,"정일환",$F:$F,"검토중") -> 0 | K6: =COUNTIFS($E:$E,"정유림",$F:$F,"검토중") -> 0 | L6: =COUNTIFS($E:$E,"김다은",$F:$F,"검토중") -> 0 | M6: =COUNTIFS($E:$E,"정혜란",$F:$F,"검토중") -> 0
B7: Activity Master | C7: ZLPAC0074 | D7: Define Posted Doc Message | E7: =VLOOKUP($B7,담당자!$C:$D,2,FALSE) -> 피재석 | F7: 검토중 | H7: 보류 | I7: =COUNTIFS($E:$E,"피재석",$F:$F,"보류") -> 0 | J7: =COUNTIFS($E:$E,"정일환",$F:$F,"보류") -> 0 | K7: =COUNTIFS($E:$E,"정유림",$F:$F,"보류") -> 0 | L7: =COUNTIFS($E:$E,"김다은",$F:$F,"보류") -> 0 | M7: =COUNTIFS($E:$E,"정혜란",$F:$F,"보류") -> 0
B8: Activity Master | C8: ZLPAC3000 | D8: Define Rework Rule ID | E8: =VLOOKUP($B8,담당자!$C:$D,2,FALSE) -> 피재석 | F8: 검토중 | H8: 합계 | I8: =SUM(I3:I7) -> 21 | J8: =SUM(J3:J7) -> 0 | K8: =SUM(K3:K7) -> 0 | L8: =SUM(L3:L7) -> 0 | M8: =SUM(M3:M7) -> 0
B9: Activity Master | C9: ZLPAC3010 | D9: Maintain Re-work Rule ID | E9: =VLOOKUP($B9,담당자!$C:$D,2,FALSE) -> 피재석 | F9: 검토중
B10: Activity Master | C10: ZLPAC3020 | D10: Define Re-work Exception Rule | E10: =VLOOKUP($B10,담당자!$C:$D,2,FALSE) -> 피재석 | G10: 확인필요
B11: ALV | C11: ZLPAC_ALV | D11: ALV Manager | E11: =VLOOKUP($B11,담당자!$C:$D,2,FALSE) -> 정일환
B12: ALV | C12: ZLPAC_ALV_CTS | D12: ALV transport | E12: =VLOOKUP($B12,담당자!$C:$D,2,FALSE) -> 정일환
B13: ALV | C13: ZLPAC_AUTOLOG | D13: Auto Logging | E13: =VLOOKUP($B13,담당자!$C:$D,2,FALSE) -> 정일환
B14: ALV | C14: ZLPACALV_EVTDEF | D14: Maintain Default Field Event | E14: =VLOOKUP($B14,담당자!$C:$D,2,FALSE) -> 정일환
B15: ALV | C15: ZLPACALVDEF | D15: Maintain Default ALV Field Catalog | E15: =VLOOKUP($B15,담당자!$C:$D,2,FALSE) -> 정일환
B16: Auth | C16: ZLPAC0080 | D16: Define Confirm(Skip) Enable Activity | E16: =VLOOKUP($B16,담당자!$C:$D,2,FALSE) -> 정유림
B17: Auth | C17: ZLPAC1000 | D17: Maintain Activity Participants | E17: =VLOOKUP($B17,담당자!$C:$D,2,FALSE) -> 정유림
B18: Auth | C18: ZLPAC1001 | D18: Copy Business Area for User Role | E18: =VLOOKUP($B18,담당자!$C:$D,2,FALSE) -> 정유림
B19: Auth | C19: ZLPAC1010 | D19: Display User Authorization | E19: =VLOOKUP($B19,담당자!$C:$D,2,FALSE) -> 정유림
B20: Auth | C20: ZLPAC1011 | D20: Closing Activity Participants | E20: =VLOOKUP($B20,담당자!$C:$D,2,FALSE) -> 정유림
B21: Auth | C21: ZLPAC1020 | D21: Display Closing Activity Participants History | E21: =VLOOKUP($B21,담당자!$C:$D,2,FALSE) -> 정유림
B22: Auth | C22: ZLPAC1030 | D22: Define Authorization Group | E22: =VLOOKUP($B22,담당자!$C:$D,2,FALSE) -> 정유림
... B36: Closing Inspection | C36: ZLPAC5310 | D36: Auto Execution for Simulation Run | E36: =VLOOKUP($B36,담당자!$C:$D,2,FALSE) -> 정유림
B37: Config | C37: ZLPAC0090 | D37: Master Configuration | E37: =VLOOKUP($B37,담당자!$C:$D,2,FALSE) -> 피재석 | F37: 검토중
B38: Config | C38: ZLPAC8010 | D38: Define Global Package ID | E38: =VLOOKUP($B38,담당자!$C:$D,2,FALSE) -> 피재석 | F38: 검토중
B39: Config | C39: ZLPAC8011 | D39: Assign Business Pkg to Global ID | E39: =VLOOKUP($B39,담당자!$C:$D,2,FALSE) -> 피재석 | F39: 검토중
B40: Config | C40: ZLPACSYS | D40: PAC System Setting | E40: =VLOOKUP($B40,담당자!$C:$D,2,FALSE) -> 피재석 | F40: 검토중
B41: Config | C41: ZLPAC0010 | D41: Maintain Business Package Config | E41: =VLOOKUP($B41,담당자!$C:$D,2,FALSE) -> 피재석 | F41: 검토중
B42: Config | C42: ZLPAC0011 | D42: Define Business Package | E42: =VLOOKUP($B42,담당자!$C:$D,2,FALSE) -> 피재석 | F42: 검토중
B43: ETC | C43: ZLPAC_CRYPTO | D43: PAC Obfuscation | E43: 정일환
B44: ETC | C44: ZLPAC_HTML | D44: PAC HTML Manager | E44: 김다은
B45: ETC | C45: ZLPAC_WIZ1000 | D45: PAC Logging Inspection | E45: 정일환
B46: ETC | C46: ZLPAC_WIZARD | D46: PAC Logging Wizard | E46: 정일환
B47: ETC | C47: ZLPACEXIT | D47: Maintain PAC User Exit | E47: 정일환
B48: ETC | C48: ZLPACMIG010 | D48: TABLE Data Upload/Downlo | E48: 정혜란
B49: ETC | C49: ZLPACMIG020 | D49: Transport Table Data | E49: 정혜란
B50: ETC | C50: ZLPACMIG030 | D50: Migration Data for DBO Table | E50: 정혜란
B51: ETC | C51: ZLPACMIG040 | D51: Migration Data for Multi Table | E51: 정혜란
B52: ETC | C52: ZLPACMIG050 | D52: Migration Data for Busin | E52: 정혜란
B53: Fiori | C53: ZLPAC_TREE | D53: Maintain Menu Tree | E53: =VLOOKUP($B53,담당자!$C:$D,2,FALSE) -> 정일환
B54: Fiori | C54: ZLPAC_TRID | D54: Define Menu Tree ID | E54: =VLOOKUP($B54,담당자!$C:$D,2,FALSE) -> 정일환
...

Sheet 구분
A3: 행 레이블 | B3: Program Id | C3: Text
A4: Activity Master | B4: ZLPAC0016 | C4: Log Collect Exception message ID
B5: ZLPAC0020 | C5: Define Activity Master
B6: ZLPAC0021 | C6: Display Detail Activity Information
B7: ZLPAC0070 | C7: Define Trigger Code
B8: ZLPAC0071 | C8: Define Locking Role
B9: ZLPAC0072 | C9: Define Common Log Parameter
B10: ZLPAC0074 | C10: Define Posted Doc Message
B11: ZLPAC3000 | C11: Define Rework Rule ID
B12: ZLPAC3010 | C12: Maintain Re-work Rule ID
B13: ZLPAC3020 | C13: Define Re-work Exception Rule
A14: ALV | B14: ZLPAC_ALV | C14: ALV Manager
B15: ZLPAC_ALV_CTS | C15: ALV transport
B16: ZLPAC_AUTOLOG | C16: Auto Logging
B17: ZLPACALV_EVTDEF | C17: Maintain Default Field Event
B18: ZLPACALVDEF | C18: Maintain Default ALV Field Catalog
A19: Auth | B19: ZLPAC0080 | C19: Define Confirm(Skip) Enable Activity
B20: ZLPAC1000 | C20: Maintain Activity Participants
B21: ZLPAC1001 | C21: Copy Business Area for User Role
B22: ZLPAC1010 | C22: Display User Authorization
B23: ZLPAC1011 | C23: Closing Activity Participants
B24: ZLPAC1020 | C24: Display Closing Activity Participants History
B25: ZLPAC1030 | C25: Define Authorization Group
B26: ZLPAC1050 | C26: Maintain Special Role
A27: Closing Inspection | B27: ZLPAC5050 | C27: Define Closing Inspection Category
B28: ZLPAC5060 | C28: Maintain Closing Inspection Scenario
B29: ZLPAC5070 | C29: Maintain Simulation Error Control
B30: ZLPAC5080 | C30: Maintain Closing Inspection Reviewer
B31: ZLPAC5090 | C31: Display Closing Inspection Reviewer
B32: ZLPAC5100 | C32: Financial Risk Validation Monitoring
B33: ZLPAC5110 | C33: Auto Execution Closing Inspection Category by Reviewer
B34: ZLPAC5111 | C34: Auto Execution for Closing Inspection Reviewer By Scenario
B35: ZLPAC5200 | C35: Closing Inspection Monitoring
B36: ZLPAC5210 | C36: Auto Execution for Closing Inspection By Category
B37: ZLPAC5211 | C37: Auto Execution for Closing Inspection By Scenario
B38: ZLPAC5300 | C38: Closing Inspection Simul.Run Monitor
B39: ZLPAC5310 | C39: Auto Execution for Simulation Run
A40: Config | B40: ZLPAC0090 | C40: Master Configuration
B41: ZLPAC8010 | C41: Define Global Package ID
B42: ZLPAC8011 | C42: Assign Business Pkg to Global ID
...

Sheet Program list
B2: Program Id | C2: Text | D2: 구분 | G2: Config
B3: ZLPAC0010 | C3: Maintain Business Package Config | D3: Config | G3: Org Mst
B4: ZLPAC0011 | C4: Define Business Package | D4: Config | G4: Activity Master
B5: ZLPAC0013 | C5: Define Business Type | D5: Org Mst | G5: Modeling
B6: ZLPAC0014 | C6: Define Node Theme Setting | D6: Fiori | G6: Schedule
B7: ZLPAC0015 | C7: Define Function Code | D7: Fiori | G7: Closing Inspection
B8: ZLPAC0016 | C8: Log Collect Exception message ID | D8: Activity Master | G8: Auth
B9: ZLPAC0017 | C9: Define Business Type By Company Code | D9: Org Mst | G9: Operation
B10: ZLPAC0018 | C10: Maintain Company Code Master | D10: Org Mst | G10: Fiori & SEGW
B11: ZLPAC0019 | C11: Maintain Business Area Master | D11: Org Mst | G11: JOB
B12: ZLPAC0020 | C12: Define Activity Master | D12: Activity Master | G12: Monitor
B13: ZLPAC0021 | C13: Display Detail Activity Information | D13: Activity Master | G13: ALV
... B15: ZLPAC0031 | C15: Maintain Global. Pkg Standard Map | D15: Modeling | G15: ETC
B16: ZLPAC0040 | C16: Maintain Organization Map | D16: Modeling
B17: ZLPAC0041 | C17: Maintain Global Pkg Organization Map | D17: Modeling
B18: ZLPAC0050 | C18: Assign Organization to Bus. Package | D18: Org Mst
B19: ZLPAC0060 | C19: Notice Management | D19: Fiori
B20: ZLPAC0070 | C20: Define Trigger Code | D20: Activity Master
B21: ZLPAC0071 | C21: Define Locking Role | D21: Activity Master
B22: ZLPAC0072 | C22: Define Common Log Parameter | D22: Activity Master
B23: ZLPAC0074 | C23: Define Posted Doc Message | D23: Activity Master
B24: ZLPAC0080 | C24: Define Confirm(Skip) Enable Activity | D24: Auth
B25: ZLPAC0090 | C25: Master Configuration | D25: Config
B26: ZLPAC0091 | C26: Maintain Region Master | D26: Org Mst
B27: ZLPAC0092 | C27: Maintain Country Master | D27: Org Mst
... B132: ZLPACALV_EVTDEF | C132: Maintain Default Field Event | D132: ALV

Sheet 담당자
B2: 순서 | C2: 구분 | D2: 딤딩자
B3: 1 | C3: Config | D3: 피재석
B4: 2 | C4: Org Mst | D4: 김다은
B5: 3 | C5: Activity Master | D5: 피재석
B6: 4 | C6: Schedule | D6: 김다은
B7: 5 | C7: Closing Inspection | D7: 정유림
B8: 6 | C8: Auth | D8: 정유림
B9: 7 | C9: JOB | D9: 정유림
B10: 8 | C10: Monitor | D10: 김다은
B11: 9 | C11: ALV | D11: 정일환
B12: 10 | C12: Todo | D12: 정혜란
B13: 11 | C13: Modeling | D13: 피재석
B14: 12 | C14: Operation | D14: 정일환
B15: 13 | C15: Fiori | D15: 정일환
